Error: An error occurred: #012Traceback (most recent call last):#012  
File "/usr/local/lib/python2.7/dist-packages/swift/common/middleware/catch_errors.py", line 41, in handle_request#012    resp = self._app_call(env)#012  
File "/usr/local/lib/python2.7/dist-packages/swift/common/wsgi.py", line 610, in _app_call#012    resp = self.app(env, self._start_response)#012  
File "/usr/local/lib/python2.7/dist-packages/swift/common/middleware/gatekeeper.py", line 90, in __call__#012    return self.app(env, gatekeeper_response)#012  
File "/usr/local/lib/python2.7/dist-packages/swift/common/middleware/healthcheck.py", line 57, in __call__#012    return self.app(env, start_response)#012  
File "/usr/local/lib/python2.7/dist-packages/swift/common/middleware/proxy_logging.py", line 297, in __call__#012    iterable = self.app(env, my_start_response)#012  
File "/usr/local/lib/python2.7/dist-packages/swift/common/middleware/memcache.py", line 108, in __call__#012    return self.app(env, start_response)#012  
File "/usr/local/lib/python2.7/dist-packages/swift/common/swob.py", line 1384, in _wsgify_self#012    return func(self, Request(env))(env, start_response)#012  
File "/usr/local/lib/python2.7/dist-packages/swift/common/swob.py", line 1384, in _wsgify_self#012    return func(self, Request(env))(env, start_response)#012  
File "/usr/local/lib/python2.7/dist-packages/swift/common/middleware/tempurl.py", line 340, in __call__#012    return self.app(env, start_response)#012  
File "/usr/local/lib/python2.7/dist-packages/swift/common/middleware/ratelimit.py", line 301, in __call__#012    return self.app(env, start_response)#012  
File "/usr/local/lib/python2.7/dist-packages/webob/dec.py", line 130, in __call__#012    resp = self.call_func(req, *args, **self.kwargs)#012  
File "/usr/local/lib/python2.7/dist-packages/webob/dec.py", line 195, in call_func#012    return self.func(req, *args, **kwargs)#012  
File "/usr/local/lib/python2.7/dist-packages/keystonemiddleware/auth_token/__init__.py", line 320, in __call__#012    response = self.process_request(req)#012  
File "/usr/local/lib/python2.7/dist-packages/keystonemiddleware/auth_token/__init__.py", line 552, in process_request#012    resp = super(AuthProtocol, self).process_request(request)#012  
File "/usr/local/lib/python2.7/dist-packages/keystonemiddleware/auth_token/__init__.py", line 348, in process_request#012    data, user_auth_ref = self._do_fetch_token(request.user_token)#012  
File "/usr/local/lib/python2.7/dist-packages/keystonemiddleware/auth_token/__init__.py", line 388, in _do_fetch_token#012    data = self.fetch_token(token)#012  
File "/usr/local/lib/python2.7/dist-packages/keystonemiddleware/auth_token/__init__.py", line 683, in fetch_token#012    data = self._identity_server.verify_token(token)#012  
File "/usr/local/lib/python2.7/dist-packages/keystonemiddleware/auth_token/_identity.py", line 214, in verify_token#012    auth_ref = self._request_strategy.verify_token(user_token)#012  
File "/usr/local/lib/python2.7/dist-packages/keystonemiddleware/auth_token/_identity.py", line 106, in verify_token#012    include_catalog=self._include_service_catalog)#012  
File "/usr/local/lib/python2.7/dist-packages/keystoneclient/utils.py", line 318, in inner#012    return func(*args, **kwargs)#012  
File "/usr/local/lib/python2.7/dist-packages/keystoneclient/v3/tokens.py", line 75, in validate#012    resp, body = self._client.get(url, headers=headers)#012  
File "/usr/local/lib/python2.7/dist-packages/keystoneclient/adapter.py", line 170, in get#012    return self.request(url, 'GET', **kwargs)#012  
File "/usr/local/lib/python2.7/dist-packages/keystoneclient/adapter.py", line 206, in request#012    resp = super(LegacyJsonAdapter, self).request(*args, **kwargs)#012  
File "/usr/local/lib/python2.7/dist-packages/keystoneclient/adapter.py", line 95, in request#012    return self.session.request(url, method, **kwargs)#012  
File "/usr/local/lib/python2.7/dist-packages/keystoneauth1/adapter.py", line 141, in request#012    return self.session.request(url, method, **kwargs)#012  
File "/usr/local/lib/python2.7/dist-packages/positional/__init__.py", line 101, in inner#012    return wrapped(*args, **kwargs)#012  
File "/usr/local/lib/python2.7/dist-packages/keystoneauth1/session.py", line 592, in request#012    resp = send(**kwargs)#012  
File "/usr/local/lib/python2.7/dist-packages/keystoneauth1/session.py", line 626, in _send_request#012    resp = self.session.request(method, url, **kwargs)#012  
File "/usr/local/lib/python2.7/dist-packages/requests/sessions.py", line 488, in request#012    resp = self.send(prep, **send_kwargs)#012  
File "/usr/local/lib/python2.7/dist-packages/requests/sessions.py", line 609, in send#012    r = adapter.send(request, **kwargs)#012  
File "/usr/local/lib/python2.7/dist-packages/requests/adapters.py", line 423, in send#012    timeout=timeout#012  
File "/usr/local/lib/python2.7/dist-packages/requests/packages/urllib3/connectionpool.py", line 588, in urlopen#012    conn = self._get_conn(timeout=pool_timeout)#012  
File "/usr/local/lib/python2.7/dist-packages/requests/packages/urllib3/connectionpool.py", line 241, in _get_conn#012    if conn and is_connection_dropped(conn):#012  
File "/usr/local/lib/python2.7/dist-packages/requests/packages/urllib3/util/connection.py", line 27, in is_connection_dropped#012    return bool(wait_for_read(sock, timeout=0.0))#012  
File "/usr/local/lib/python2.7/dist-packages/requests/packages/urllib3/util/wait.py", line 33, in wait_for_read#012    return _wait_for_io_events(socks, EVENT_READ, timeout)#012  
File "/usr/local/lib/python2.7/dist-packages/requests/packages/urllib3/util/wait.py", line 22, in _wait_for_io_events#012    with DefaultSelector() as selector:#012  
File "/usr/local/lib/python2.7/dist-packages/requests/packages/urllib3/util/selectors.py", line 364, in __init__#012    self._epoll = select.epoll()#012AttributeError: 'module' object has no attribute 'epoll' (txn: txb6f03e716a77413aa3e2b-0058b543d8)
Feb 28 10:33:12 iostack-proxy proxy-server: STDERR: 10.30.1.5 - - [28/Feb/2017 09:33:12] "GET /v1/AUTH_5a05806e477d40dbb2eed40444e50e51/BSC/file1 HTTP/1.1" 500 179 0.013920 (txn: txb6f03e716a77413aa3e2b-0058b543d8)
